[2025-09-10T07:17:21.542+0000] {taskinstance.py:1159} INFO - Dependencies all met for dep_context=non-requeueable deps ti=<TaskInstance: spotify_etl_pipeline.load_songs manual__2025-09-10T07:05:36.771044+00:00 [queued]>
[2025-09-10T07:17:21.549+0000] {taskinstance.py:1159} INFO - Dependencies all met for dep_context=requeueable deps ti=<TaskInstance: spotify_etl_pipeline.load_songs manual__2025-09-10T07:05:36.771044+00:00 [queued]>
[2025-09-10T07:17:21.549+0000] {taskinstance.py:1361} INFO - Starting attempt 2 of 2
[2025-09-10T07:17:21.565+0000] {taskinstance.py:1382} INFO - Executing <Task(PythonOperator): load_songs> on 2025-09-10 07:05:36.771044+00:00
[2025-09-10T07:17:21.589+0000] {standard_task_runner.py:57} INFO - Started process 226 to run task
[2025-09-10T07:17:21.594+0000] {standard_task_runner.py:84} INFO - Running: ['***', 'tasks', 'run', 'spotify_etl_pipeline', 'load_songs', 'manual__2025-09-10T07:05:36.771044+00:00', '--job-id', '8', '--raw', '--subdir', 'DAGS_FOLDER/spotify_dag.py', '--cfg-path', '/tmp/tmp_zdioes7']
[2025-09-10T07:17:21.598+0000] {standard_task_runner.py:85} INFO - Job 8: Subtask load_songs
[2025-09-10T07:17:21.643+0000] {task_command.py:415} INFO - Running <TaskInstance: spotify_etl_pipeline.load_songs manual__2025-09-10T07:05:36.771044+00:00 [running]> on host f0eab26dbb86
[2025-09-10T07:17:22.037+0000] {taskinstance.py:1660} INFO - Exporting env vars: AIRFLOW_CTX_DAG_OWNER='***' AIRFLOW_CTX_DAG_ID='spotify_etl_pipeline' AIRFLOW_CTX_TASK_ID='load_songs' AIRFLOW_CTX_EXECUTION_DATE='2025-09-10T07:05:36.771044+00:00' AIRFLOW_CTX_TRY_NUMBER='2' AIRFLOW_CTX_DAG_RUN_ID='manual__2025-09-10T07:05:36.771044+00:00'
[2025-09-10T07:17:22.043+0000] {taskinstance.py:1943} ERROR - Task failed with exception
Traceback (most recent call last):
  File "/home/airflow/.local/lib/python3.8/site-packages/airflow/operators/python.py", line 192, in execute
    return_value = self.execute_callable()
  File "/home/airflow/.local/lib/python3.8/site-packages/airflow/operators/python.py", line 209, in execute_callable
    return self.python_callable(*self.op_args, **self.op_kwargs)
  File "/opt/airflow/etl/load.py", line 8, in load_songs_from_csv
    df = pd.read_csv(csv_path)
  File "/home/airflow/.local/lib/python3.8/site-packages/pandas/io/parsers/readers.py", line 912, in read_csv
    return _read(filepath_or_buffer, kwds)
  File "/home/airflow/.local/lib/python3.8/site-packages/pandas/io/parsers/readers.py", line 577, in _read
    parser = TextFileReader(filepath_or_buffer, **kwds)
  File "/home/airflow/.local/lib/python3.8/site-packages/pandas/io/parsers/readers.py", line 1407, in __init__
    self._engine = self._make_engine(f, self.engine)
  File "/home/airflow/.local/lib/python3.8/site-packages/pandas/io/parsers/readers.py", line 1661, in _make_engine
    self.handles = get_handle(
  File "/home/airflow/.local/lib/python3.8/site-packages/pandas/io/common.py", line 859, in get_handle
    handle = open(
FileNotFoundError: [Errno 2] No such file or directory: '../data/recent_songs.csv'
[2025-09-10T07:17:22.090+0000] {taskinstance.py:1400} INFO - Marking task as FAILED. dag_id=spotify_etl_pipeline, task_id=load_songs, execution_date=20250910T070536, start_date=20250910T071721, end_date=20250910T071722
[2025-09-10T07:17:22.124+0000] {standard_task_runner.py:104} ERROR - Failed to execute job 8 for task load_songs ([Errno 2] No such file or directory: '../data/recent_songs.csv'; 226)
[2025-09-10T07:17:22.153+0000] {local_task_job_runner.py:228} INFO - Task exited with return code 1
[2025-09-10T07:17:22.175+0000] {taskinstance.py:2784} INFO - 0 downstream tasks scheduled from follow-on schedule check
