[2025-09-28T13:43:22.128+0000] {taskinstance.py:1159} INFO - Dependencies all met for dep_context=non-requeueable deps ti=<TaskInstance: spotify_etl_pipeline.extract_genres scheduled__2025-09-28T12:00:00+00:00 [queued]>
[2025-09-28T13:43:22.140+0000] {taskinstance.py:1159} INFO - Dependencies all met for dep_context=requeueable deps ti=<TaskInstance: spotify_etl_pipeline.extract_genres scheduled__2025-09-28T12:00:00+00:00 [queued]>
[2025-09-28T13:43:22.141+0000] {taskinstance.py:1361} INFO - Starting attempt 2 of 6
[2025-09-28T13:43:22.160+0000] {taskinstance.py:1382} INFO - Executing <Task(PythonOperator): extract_genres> on 2025-09-28 12:00:00+00:00
[2025-09-28T13:43:22.167+0000] {standard_task_runner.py:57} INFO - Started process 92699 to run task
[2025-09-28T13:43:22.171+0000] {standard_task_runner.py:84} INFO - Running: ['***', 'tasks', 'run', 'spotify_etl_pipeline', 'extract_genres', 'scheduled__2025-09-28T12:00:00+00:00', '--job-id', '2709', '--raw', '--subdir', 'DAGS_FOLDER/spotify_dag.py', '--cfg-path', '/tmp/tmpsjdfc_k7']
[2025-09-28T13:43:22.175+0000] {standard_task_runner.py:85} INFO - Job 2709: Subtask extract_genres
[2025-09-28T13:43:22.675+0000] {task_command.py:415} INFO - Running <TaskInstance: spotify_etl_pipeline.extract_genres scheduled__2025-09-28T12:00:00+00:00 [running]> on host 8522660cfb6a
[2025-09-28T13:43:22.794+0000] {taskinstance.py:1660} INFO - Exporting env vars: AIRFLOW_CTX_DAG_OWNER='***' AIRFLOW_CTX_DAG_ID='spotify_etl_pipeline' AIRFLOW_CTX_TASK_ID='extract_genres' AIRFLOW_CTX_EXECUTION_DATE='2025-09-28T12:00:00+00:00' AIRFLOW_CTX_TRY_NUMBER='2' AIRFLOW_CTX_DAG_RUN_ID='scheduled__2025-09-28T12:00:00+00:00'
[2025-09-28T13:43:45.872+0000] {taskinstance.py:1943} ERROR - Task failed with exception
Traceback (most recent call last):
  File "/home/airflow/.local/lib/python3.8/site-packages/urllib3/connectionpool.py", line 714, in urlopen
    httplib_response = self._make_request(
  File "/home/airflow/.local/lib/python3.8/site-packages/urllib3/connectionpool.py", line 403, in _make_request
    self._validate_conn(conn)
  File "/home/airflow/.local/lib/python3.8/site-packages/urllib3/connectionpool.py", line 1053, in _validate_conn
    conn.connect()
  File "/home/airflow/.local/lib/python3.8/site-packages/urllib3/connection.py", line 419, in connect
    self.sock = ssl_wrap_socket(
  File "/home/airflow/.local/lib/python3.8/site-packages/urllib3/util/ssl_.py", line 449, in ssl_wrap_socket
    ssl_sock = _ssl_wrap_socket_impl(
  File "/home/airflow/.local/lib/python3.8/site-packages/urllib3/util/ssl_.py", line 493, in _ssl_wrap_socket_impl
    return ssl_context.wrap_socket(sock, server_hostname=server_hostname)
  File "/usr/local/lib/python3.8/ssl.py", line 500, in wrap_socket
    return self.sslsocket_class._create(
  File "/usr/local/lib/python3.8/ssl.py", line 1040, in _create
    self.do_handshake()
  File "/usr/local/lib/python3.8/ssl.py", line 1309, in do_handshake
    self._sslobj.do_handshake()
ssl.SSLEOFError: EOF occurred in violation of protocol (_ssl.c:1131)

During handling of the above exception, another exception occurred:

Traceback (most recent call last):
  File "/home/airflow/.local/lib/python3.8/site-packages/requests/adapters.py", line 486, in send
    resp = conn.urlopen(
  File "/home/airflow/.local/lib/python3.8/site-packages/urllib3/connectionpool.py", line 798, in urlopen
    retries = retries.increment(
  File "/home/airflow/.local/lib/python3.8/site-packages/urllib3/util/retry.py", line 592, in increment
    raise MaxRetryError(_pool, url, error or ResponseError(cause))
urllib3.exceptions.MaxRetryError: HTTPSConnectionPool(host='api.spotify.com', port=443): Max retries exceeded with url: /v1/artists/00FQb4jTyendYWaN8pK0wa (Caused by SSLError(SSLEOFError(8, 'EOF occurred in violation of protocol (_ssl.c:1131)')))

During handling of the above exception, another exception occurred:

Traceback (most recent call last):
  File "/home/airflow/.local/lib/python3.8/site-packages/airflow/operators/python.py", line 192, in execute
    return_value = self.execute_callable()
  File "/home/airflow/.local/lib/python3.8/site-packages/airflow/operators/python.py", line 209, in execute_callable
    return self.python_callable(*self.op_args, **self.op_kwargs)
  File "/opt/airflow/dags/spotify_dag.py", line 52, in extract_genres_task
    fetch_artist_genres(df["artist_id"].tolist())
  File "/opt/airflow/etl/extract.py", line 95, in fetch_artist_genres
    response = requests.get(url, headers=headers, timeout=30)
  File "/home/airflow/.local/lib/python3.8/site-packages/requests/api.py", line 73, in get
    return request("get", url, params=params, **kwargs)
  File "/home/airflow/.local/lib/python3.8/site-packages/requests/api.py", line 59, in request
    return session.request(method=method, url=url, **kwargs)
  File "/home/airflow/.local/lib/python3.8/site-packages/requests/sessions.py", line 589, in request
    resp = self.send(prep, **send_kwargs)
  File "/home/airflow/.local/lib/python3.8/site-packages/requests/sessions.py", line 703, in send
    r = adapter.send(request, **kwargs)
  File "/home/airflow/.local/lib/python3.8/site-packages/requests/adapters.py", line 517, in send
    raise SSLError(e, request=request)
requests.exceptions.SSLError: HTTPSConnectionPool(host='api.spotify.com', port=443): Max retries exceeded with url: /v1/artists/00FQb4jTyendYWaN8pK0wa (Caused by SSLError(SSLEOFError(8, 'EOF occurred in violation of protocol (_ssl.c:1131)')))
[2025-09-28T13:43:45.936+0000] {taskinstance.py:1400} INFO - Marking task as UP_FOR_RETRY. dag_id=spotify_etl_pipeline, task_id=extract_genres, execution_date=20250928T120000, start_date=20250928T134322, end_date=20250928T134345
[2025-09-28T13:43:45.962+0000] {standard_task_runner.py:104} ERROR - Failed to execute job 2709 for task extract_genres (HTTPSConnectionPool(host='api.spotify.com', port=443): Max retries exceeded with url: /v1/artists/00FQb4jTyendYWaN8pK0wa (Caused by SSLError(SSLEOFError(8, 'EOF occurred in violation of protocol (_ssl.c:1131)'))); 92699)
[2025-09-28T13:43:46.018+0000] {local_task_job_runner.py:228} INFO - Task exited with return code 1
[2025-09-28T13:43:46.484+0000] {taskinstance.py:2784} INFO - 0 downstream tasks scheduled from follow-on schedule check
