[2025-09-10T07:12:18.060+0000] {taskinstance.py:1159} INFO - Dependencies all met for dep_context=non-requeueable deps ti=<TaskInstance: spotify_etl_pipeline.load_genres manual__2025-09-10T07:05:36.771044+00:00 [queued]>
[2025-09-10T07:12:18.077+0000] {taskinstance.py:1159} INFO - Dependencies all met for dep_context=requeueable deps ti=<TaskInstance: spotify_etl_pipeline.load_genres manual__2025-09-10T07:05:36.771044+00:00 [queued]>
[2025-09-10T07:12:18.077+0000] {taskinstance.py:1361} INFO - Starting attempt 1 of 2
[2025-09-10T07:12:18.100+0000] {taskinstance.py:1382} INFO - Executing <Task(PythonOperator): load_genres> on 2025-09-10 07:05:36.771044+00:00
[2025-09-10T07:12:18.111+0000] {standard_task_runner.py:57} INFO - Started process 186 to run task
[2025-09-10T07:12:18.116+0000] {standard_task_runner.py:84} INFO - Running: ['***', 'tasks', 'run', 'spotify_etl_pipeline', 'load_genres', 'manual__2025-09-10T07:05:36.771044+00:00', '--job-id', '5', '--raw', '--subdir', 'DAGS_FOLDER/spotify_dag.py', '--cfg-path', '/tmp/tmpvm2hbq9r']
[2025-09-10T07:12:18.120+0000] {standard_task_runner.py:85} INFO - Job 5: Subtask load_genres
[2025-09-10T07:12:18.175+0000] {task_command.py:415} INFO - Running <TaskInstance: spotify_etl_pipeline.load_genres manual__2025-09-10T07:05:36.771044+00:00 [running]> on host edbc0dc7d2db
[2025-09-10T07:12:18.250+0000] {taskinstance.py:1660} INFO - Exporting env vars: AIRFLOW_CTX_DAG_OWNER='***' AIRFLOW_CTX_DAG_ID='spotify_etl_pipeline' AIRFLOW_CTX_TASK_ID='load_genres' AIRFLOW_CTX_EXECUTION_DATE='2025-09-10T07:05:36.771044+00:00' AIRFLOW_CTX_TRY_NUMBER='1' AIRFLOW_CTX_DAG_RUN_ID='manual__2025-09-10T07:05:36.771044+00:00'
[2025-09-10T07:12:18.255+0000] {taskinstance.py:1943} ERROR - Task failed with exception
Traceback (most recent call last):
  File "/home/airflow/.local/lib/python3.8/site-packages/airflow/operators/python.py", line 192, in execute
    return_value = self.execute_callable()
  File "/home/airflow/.local/lib/python3.8/site-packages/airflow/operators/python.py", line 209, in execute_callable
    return self.python_callable(*self.op_args, **self.op_kwargs)
  File "/opt/airflow/etl/load.py", line 34, in load_genres_from_csv
    df = pd.read_csv(csv_path)
  File "/home/airflow/.local/lib/python3.8/site-packages/pandas/io/parsers/readers.py", line 912, in read_csv
    return _read(filepath_or_buffer, kwds)
  File "/home/airflow/.local/lib/python3.8/site-packages/pandas/io/parsers/readers.py", line 577, in _read
    parser = TextFileReader(filepath_or_buffer, **kwds)
  File "/home/airflow/.local/lib/python3.8/site-packages/pandas/io/parsers/readers.py", line 1407, in __init__
    self._engine = self._make_engine(f, self.engine)
  File "/home/airflow/.local/lib/python3.8/site-packages/pandas/io/parsers/readers.py", line 1661, in _make_engine
    self.handles = get_handle(
  File "/home/airflow/.local/lib/python3.8/site-packages/pandas/io/common.py", line 859, in get_handle
    handle = open(
FileNotFoundError: [Errno 2] No such file or directory: '../data/recent_genres.csv'
[2025-09-10T07:12:18.268+0000] {taskinstance.py:1400} INFO - Marking task as UP_FOR_RETRY. dag_id=spotify_etl_pipeline, task_id=load_genres, execution_date=20250910T070536, start_date=20250910T071218, end_date=20250910T071218
[2025-09-10T07:12:18.279+0000] {standard_task_runner.py:104} ERROR - Failed to execute job 5 for task load_genres ([Errno 2] No such file or directory: '../data/recent_genres.csv'; 186)
[2025-09-10T07:12:18.297+0000] {local_task_job_runner.py:228} INFO - Task exited with return code 1
[2025-09-10T07:12:18.331+0000] {taskinstance.py:2784} INFO - 0 downstream tasks scheduled from follow-on schedule check
