[2025-09-12T05:53:58.796+0000] {taskinstance.py:1159} INFO - Dependencies all met for dep_context=non-requeueable deps ti=<TaskInstance: spotify_saved_tracks_etl_pipeline.gold_saved_transform manual__2025-09-12T05:25:38.314730+00:00 [queued]>
[2025-09-12T05:53:58.802+0000] {taskinstance.py:1159} INFO - Dependencies all met for dep_context=requeueable deps ti=<TaskInstance: spotify_saved_tracks_etl_pipeline.gold_saved_transform manual__2025-09-12T05:25:38.314730+00:00 [queued]>
[2025-09-12T05:53:58.802+0000] {taskinstance.py:1361} INFO - Starting attempt 5 of 6
[2025-09-12T05:53:58.884+0000] {taskinstance.py:1382} INFO - Executing <Task(PythonOperator): gold_saved_transform> on 2025-09-12 05:25:38.314730+00:00
[2025-09-12T05:53:58.889+0000] {standard_task_runner.py:57} INFO - Started process 24905 to run task
[2025-09-12T05:53:58.893+0000] {standard_task_runner.py:84} INFO - Running: ['***', 'tasks', 'run', 'spotify_saved_tracks_etl_pipeline', 'gold_saved_transform', 'manual__2025-09-12T05:25:38.314730+00:00', '--job-id', '314', '--raw', '--subdir', 'DAGS_FOLDER/spotify_saved_dag.py', '--cfg-path', '/tmp/tmpniync0s8']
[2025-09-12T05:53:58.896+0000] {standard_task_runner.py:85} INFO - Job 314: Subtask gold_saved_transform
[2025-09-12T05:53:58.936+0000] {task_command.py:415} INFO - Running <TaskInstance: spotify_saved_tracks_etl_pipeline.gold_saved_transform manual__2025-09-12T05:25:38.314730+00:00 [running]> on host 0d0cd054d690
[2025-09-12T05:53:58.991+0000] {taskinstance.py:1660} INFO - Exporting env vars: AIRFLOW_CTX_DAG_OWNER='***' AIRFLOW_CTX_DAG_ID='spotify_saved_tracks_etl_pipeline' AIRFLOW_CTX_TASK_ID='gold_saved_transform' AIRFLOW_CTX_EXECUTION_DATE='2025-09-12T05:25:38.314730+00:00' AIRFLOW_CTX_TRY_NUMBER='5' AIRFLOW_CTX_DAG_RUN_ID='manual__2025-09-12T05:25:38.314730+00:00'
[2025-09-12T05:53:59.000+0000] {taskinstance.py:1943} ERROR - Task failed with exception
Traceback (most recent call last):
  File "/home/airflow/.local/lib/python3.8/site-packages/airflow/operators/python.py", line 192, in execute
    return_value = self.execute_callable()
  File "/home/airflow/.local/lib/python3.8/site-packages/airflow/operators/python.py", line 209, in execute_callable
    return self.python_callable(*self.op_args, **self.op_kwargs)
  File "/opt/airflow/etl/db_utils.py", line 11, in run_sql_scripts
    cur.execute(sql)
psycopg2.errors.UndefinedTable: missing FROM-clause entry for table "s"
LINE 7:  s.track_id,
         ^

[2025-09-12T05:53:59.014+0000] {taskinstance.py:1400} INFO - Marking task as UP_FOR_RETRY. dag_id=spotify_saved_tracks_etl_pipeline, task_id=gold_saved_transform, execution_date=20250912T052538, start_date=20250912T055358, end_date=20250912T055359
[2025-09-12T05:53:59.026+0000] {standard_task_runner.py:104} ERROR - Failed to execute job 314 for task gold_saved_transform (missing FROM-clause entry for table "s"
LINE 7:  s.track_id,
         ^
; 24905)
[2025-09-12T05:53:59.035+0000] {local_task_job_runner.py:228} INFO - Task exited with return code 1
[2025-09-12T05:53:59.049+0000] {taskinstance.py:2784} INFO - 0 downstream tasks scheduled from follow-on schedule check
