[2025-09-12T05:12:34.454+0000] {taskinstance.py:1159} INFO - Dependencies all met for dep_context=non-requeueable deps ti=<TaskInstance: spotify_etl_pipeline.gold_transform manual__2025-09-12T05:12:14.606746+00:00 [queued]>
[2025-09-12T05:12:34.462+0000] {taskinstance.py:1159} INFO - Dependencies all met for dep_context=requeueable deps ti=<TaskInstance: spotify_etl_pipeline.gold_transform manual__2025-09-12T05:12:14.606746+00:00 [queued]>
[2025-09-12T05:12:34.463+0000] {taskinstance.py:1361} INFO - Starting attempt 1 of 2
[2025-09-12T05:12:34.473+0000] {taskinstance.py:1382} INFO - Executing <Task(PythonOperator): gold_transform> on 2025-09-12 05:12:14.606746+00:00
[2025-09-12T05:12:34.493+0000] {standard_task_runner.py:57} INFO - Started process 23360 to run task
[2025-09-12T05:12:34.504+0000] {standard_task_runner.py:84} INFO - Running: ['***', 'tasks', 'run', 'spotify_etl_pipeline', 'gold_transform', 'manual__2025-09-12T05:12:14.606746+00:00', '--job-id', '283', '--raw', '--subdir', 'DAGS_FOLDER/spotify_dag.py', '--cfg-path', '/tmp/tmpj4yiqkrm']
[2025-09-12T05:12:34.509+0000] {standard_task_runner.py:85} INFO - Job 283: Subtask gold_transform
[2025-09-12T05:12:34.554+0000] {task_command.py:415} INFO - Running <TaskInstance: spotify_etl_pipeline.gold_transform manual__2025-09-12T05:12:14.606746+00:00 [running]> on host 0d0cd054d690
[2025-09-12T05:12:34.655+0000] {taskinstance.py:1660} INFO - Exporting env vars: AIRFLOW_CTX_DAG_OWNER='***' AIRFLOW_CTX_DAG_ID='spotify_etl_pipeline' AIRFLOW_CTX_TASK_ID='gold_transform' AIRFLOW_CTX_EXECUTION_DATE='2025-09-12T05:12:14.606746+00:00' AIRFLOW_CTX_TRY_NUMBER='1' AIRFLOW_CTX_DAG_RUN_ID='manual__2025-09-12T05:12:14.606746+00:00'
[2025-09-12T05:12:34.675+0000] {taskinstance.py:1943} ERROR - Task failed with exception
Traceback (most recent call last):
  File "/home/airflow/.local/lib/python3.8/site-packages/airflow/operators/python.py", line 192, in execute
    return_value = self.execute_callable()
  File "/home/airflow/.local/lib/python3.8/site-packages/airflow/operators/python.py", line 209, in execute_callable
    return self.python_callable(*self.op_args, **self.op_kwargs)
  File "/opt/airflow/etl/db_utils.py", line 11, in run_sql_scripts
    cur.execute(sql)
psycopg2.errors.UndefinedTable: missing FROM-clause entry for table "s"
LINE 6:     ROW_NUMBER() OVER (ORDER BY s.played_at_myt) AS fact_lis...
                                        ^

[2025-09-12T05:12:35.075+0000] {taskinstance.py:1400} INFO - Marking task as UP_FOR_RETRY. dag_id=spotify_etl_pipeline, task_id=gold_transform, execution_date=20250912T051214, start_date=20250912T051234, end_date=20250912T051235
[2025-09-12T05:12:35.094+0000] {standard_task_runner.py:104} ERROR - Failed to execute job 283 for task gold_transform (missing FROM-clause entry for table "s"
LINE 6:     ROW_NUMBER() OVER (ORDER BY s.played_at_myt) AS fact_lis...
                                        ^
; 23360)
[2025-09-12T05:12:35.141+0000] {local_task_job_runner.py:228} INFO - Task exited with return code 1
[2025-09-12T05:12:35.174+0000] {taskinstance.py:2784} INFO - 0 downstream tasks scheduled from follow-on schedule check
