[2025-09-12T05:32:32.487+0000] {taskinstance.py:1159} INFO - Dependencies all met for dep_context=non-requeueable deps ti=<TaskInstance: spotify_saved_tracks_etl_pipeline.gold_saved_transform manual__2025-09-12T05:20:59.612932+00:00 [queued]>
[2025-09-12T05:32:32.503+0000] {taskinstance.py:1159} INFO - Dependencies all met for dep_context=requeueable deps ti=<TaskInstance: spotify_saved_tracks_etl_pipeline.gold_saved_transform manual__2025-09-12T05:20:59.612932+00:00 [queued]>
[2025-09-12T05:32:32.503+0000] {taskinstance.py:1361} INFO - Starting attempt 2 of 2
[2025-09-12T05:32:32.596+0000] {taskinstance.py:1382} INFO - Executing <Task(PythonOperator): gold_saved_transform> on 2025-09-12 05:20:59.612932+00:00
[2025-09-12T05:32:32.603+0000] {standard_task_runner.py:57} INFO - Started process 24128 to run task
[2025-09-12T05:32:32.606+0000] {standard_task_runner.py:84} INFO - Running: ['***', 'tasks', 'run', 'spotify_saved_tracks_etl_pipeline', 'gold_saved_transform', 'manual__2025-09-12T05:20:59.612932+00:00', '--job-id', '303', '--raw', '--subdir', 'DAGS_FOLDER/spotify_saved_dag.py', '--cfg-path', '/tmp/tmpxbt6iaif']
[2025-09-12T05:32:32.608+0000] {standard_task_runner.py:85} INFO - Job 303: Subtask gold_saved_transform
[2025-09-12T05:32:32.641+0000] {task_command.py:415} INFO - Running <TaskInstance: spotify_saved_tracks_etl_pipeline.gold_saved_transform manual__2025-09-12T05:20:59.612932+00:00 [running]> on host 0d0cd054d690
[2025-09-12T05:32:32.696+0000] {taskinstance.py:1660} INFO - Exporting env vars: AIRFLOW_CTX_DAG_OWNER='***' AIRFLOW_CTX_DAG_ID='spotify_saved_tracks_etl_pipeline' AIRFLOW_CTX_TASK_ID='gold_saved_transform' AIRFLOW_CTX_EXECUTION_DATE='2025-09-12T05:20:59.612932+00:00' AIRFLOW_CTX_TRY_NUMBER='2' AIRFLOW_CTX_DAG_RUN_ID='manual__2025-09-12T05:20:59.612932+00:00'
[2025-09-12T05:32:32.705+0000] {taskinstance.py:1943} ERROR - Task failed with exception
Traceback (most recent call last):
  File "/home/airflow/.local/lib/python3.8/site-packages/airflow/operators/python.py", line 192, in execute
    return_value = self.execute_callable()
  File "/home/airflow/.local/lib/python3.8/site-packages/airflow/operators/python.py", line 209, in execute_callable
    return self.python_callable(*self.op_args, **self.op_kwargs)
  File "/opt/airflow/etl/db_utils.py", line 11, in run_sql_scripts
    cur.execute(sql)
psycopg2.errors.UndefinedTable: missing FROM-clause entry for table "s"
LINE 7:  s.track_id,
         ^

[2025-09-12T05:32:32.711+0000] {taskinstance.py:1400} INFO - Marking task as FAILED. dag_id=spotify_saved_tracks_etl_pipeline, task_id=gold_saved_transform, execution_date=20250912T052059, start_date=20250912T053232, end_date=20250912T053232
[2025-09-12T05:32:32.720+0000] {standard_task_runner.py:104} ERROR - Failed to execute job 303 for task gold_saved_transform (missing FROM-clause entry for table "s"
LINE 7:  s.track_id,
         ^
; 24128)
[2025-09-12T05:32:32.748+0000] {local_task_job_runner.py:228} INFO - Task exited with return code 1
[2025-09-12T05:32:32.764+0000] {taskinstance.py:2784} INFO - 0 downstream tasks scheduled from follow-on schedule check
