[2025-09-26T03:17:06.884+0000] {taskinstance.py:1159} INFO - Dependencies all met for dep_context=non-requeueable deps ti=<TaskInstance: spotify_etl_pipeline.extract_songs scheduled__2025-09-25T15:00:00+00:00 [queued]>
[2025-09-26T03:17:06.913+0000] {taskinstance.py:1159} INFO - Dependencies all met for dep_context=requeueable deps ti=<TaskInstance: spotify_etl_pipeline.extract_songs scheduled__2025-09-25T15:00:00+00:00 [queued]>
[2025-09-26T03:17:06.916+0000] {taskinstance.py:1361} INFO - Starting attempt 2 of 6
[2025-09-26T03:17:07.000+0000] {taskinstance.py:1382} INFO - Executing <Task(PythonOperator): extract_songs> on 2025-09-25 15:00:00+00:00
[2025-09-26T03:17:07.020+0000] {standard_task_runner.py:57} INFO - Started process 15642 to run task
[2025-09-26T03:17:07.036+0000] {standard_task_runner.py:84} INFO - Running: ['***', 'tasks', 'run', 'spotify_etl_pipeline', 'extract_songs', 'scheduled__2025-09-25T15:00:00+00:00', '--job-id', '2268', '--raw', '--subdir', 'DAGS_FOLDER/spotify_dag.py', '--cfg-path', '/tmp/tmpm4vanftz']
[2025-09-26T03:17:07.078+0000] {standard_task_runner.py:85} INFO - Job 2268: Subtask extract_songs
[2025-09-26T03:17:07.936+0000] {task_command.py:415} INFO - Running <TaskInstance: spotify_etl_pipeline.extract_songs scheduled__2025-09-25T15:00:00+00:00 [running]> on host 8522660cfb6a
[2025-09-26T03:17:08.056+0000] {taskinstance.py:1660} INFO - Exporting env vars: AIRFLOW_CTX_DAG_OWNER='***' AIRFLOW_CTX_DAG_ID='spotify_etl_pipeline' AIRFLOW_CTX_TASK_ID='extract_songs' AIRFLOW_CTX_EXECUTION_DATE='2025-09-25T15:00:00+00:00' AIRFLOW_CTX_TRY_NUMBER='2' AIRFLOW_CTX_DAG_RUN_ID='scheduled__2025-09-25T15:00:00+00:00'
[2025-09-26T03:17:12.910+0000] {taskinstance.py:1943} ERROR - Task failed with exception
Traceback (most recent call last):
  File "/home/airflow/.local/lib/python3.8/site-packages/urllib3/connectionpool.py", line 714, in urlopen
    httplib_response = self._make_request(
  File "/home/airflow/.local/lib/python3.8/site-packages/urllib3/connectionpool.py", line 403, in _make_request
    self._validate_conn(conn)
  File "/home/airflow/.local/lib/python3.8/site-packages/urllib3/connectionpool.py", line 1053, in _validate_conn
    conn.connect()
  File "/home/airflow/.local/lib/python3.8/site-packages/urllib3/connection.py", line 419, in connect
    self.sock = ssl_wrap_socket(
  File "/home/airflow/.local/lib/python3.8/site-packages/urllib3/util/ssl_.py", line 449, in ssl_wrap_socket
    ssl_sock = _ssl_wrap_socket_impl(
  File "/home/airflow/.local/lib/python3.8/site-packages/urllib3/util/ssl_.py", line 493, in _ssl_wrap_socket_impl
    return ssl_context.wrap_socket(sock, server_hostname=server_hostname)
  File "/usr/local/lib/python3.8/ssl.py", line 500, in wrap_socket
    return self.sslsocket_class._create(
  File "/usr/local/lib/python3.8/ssl.py", line 1040, in _create
    self.do_handshake()
  File "/usr/local/lib/python3.8/ssl.py", line 1309, in do_handshake
    self._sslobj.do_handshake()
ssl.SSLEOFError: EOF occurred in violation of protocol (_ssl.c:1131)

During handling of the above exception, another exception occurred:

Traceback (most recent call last):
  File "/home/airflow/.local/lib/python3.8/site-packages/requests/adapters.py", line 486, in send
    resp = conn.urlopen(
  File "/home/airflow/.local/lib/python3.8/site-packages/urllib3/connectionpool.py", line 798, in urlopen
    retries = retries.increment(
  File "/home/airflow/.local/lib/python3.8/site-packages/urllib3/util/retry.py", line 592, in increment
    raise MaxRetryError(_pool, url, error or ResponseError(cause))
urllib3.exceptions.MaxRetryError: HTTPSConnectionPool(host='api.spotify.com', port=443): Max retries exceeded with url: /v1/artists/00FQb4jTyendYWaN8pK0wa (Caused by SSLError(SSLEOFError(8, 'EOF occurred in violation of protocol (_ssl.c:1131)')))

During handling of the above exception, another exception occurred:

Traceback (most recent call last):
  File "/home/airflow/.local/lib/python3.8/site-packages/airflow/operators/python.py", line 192, in execute
    return_value = self.execute_callable()
  File "/home/airflow/.local/lib/python3.8/site-packages/airflow/operators/python.py", line 209, in execute_callable
    return self.python_callable(*self.op_args, **self.op_kwargs)
  File "/opt/airflow/etl/extract.py", line 79, in fetch_recent_played
    artist_image_df = fetch_artist_images(list(artist_ids))
  File "/opt/airflow/etl/extract.py", line 27, in fetch_artist_images
    response = requests.get(url, headers=headers, timeout=30)
  File "/home/airflow/.local/lib/python3.8/site-packages/requests/api.py", line 73, in get
    return request("get", url, params=params, **kwargs)
  File "/home/airflow/.local/lib/python3.8/site-packages/requests/api.py", line 59, in request
    return session.request(method=method, url=url, **kwargs)
  File "/home/airflow/.local/lib/python3.8/site-packages/requests/sessions.py", line 589, in request
    resp = self.send(prep, **send_kwargs)
  File "/home/airflow/.local/lib/python3.8/site-packages/requests/sessions.py", line 703, in send
    r = adapter.send(request, **kwargs)
  File "/home/airflow/.local/lib/python3.8/site-packages/requests/adapters.py", line 517, in send
    raise SSLError(e, request=request)
requests.exceptions.SSLError: HTTPSConnectionPool(host='api.spotify.com', port=443): Max retries exceeded with url: /v1/artists/00FQb4jTyendYWaN8pK0wa (Caused by SSLError(SSLEOFError(8, 'EOF occurred in violation of protocol (_ssl.c:1131)')))
[2025-09-26T03:17:12.946+0000] {taskinstance.py:1400} INFO - Marking task as UP_FOR_RETRY. dag_id=spotify_etl_pipeline, task_id=extract_songs, execution_date=20250925T150000, start_date=20250926T031706, end_date=20250926T031712
[2025-09-26T03:17:12.970+0000] {standard_task_runner.py:104} ERROR - Failed to execute job 2268 for task extract_songs (HTTPSConnectionPool(host='api.spotify.com', port=443): Max retries exceeded with url: /v1/artists/00FQb4jTyendYWaN8pK0wa (Caused by SSLError(SSLEOFError(8, 'EOF occurred in violation of protocol (_ssl.c:1131)'))); 15642)
[2025-09-26T03:17:13.025+0000] {local_task_job_runner.py:228} INFO - Task exited with return code 1
[2025-09-26T03:17:13.358+0000] {taskinstance.py:2784} INFO - 0 downstream tasks scheduled from follow-on schedule check
