[2025-09-16T02:29:33.697+0000] {taskinstance.py:1159} INFO - Dependencies all met for dep_context=non-requeueable deps ti=<TaskInstance: spotify_etl_pipeline.gold_transform scheduled__2025-09-15T15:00:00+00:00 [queued]>
[2025-09-16T02:29:33.704+0000] {taskinstance.py:1159} INFO - Dependencies all met for dep_context=requeueable deps ti=<TaskInstance: spotify_etl_pipeline.gold_transform scheduled__2025-09-15T15:00:00+00:00 [queued]>
[2025-09-16T02:29:33.705+0000] {taskinstance.py:1361} INFO - Starting attempt 5 of 6
[2025-09-16T02:29:33.714+0000] {taskinstance.py:1382} INFO - Executing <Task(PythonOperator): gold_transform> on 2025-09-15 15:00:00+00:00
[2025-09-16T02:29:33.720+0000] {standard_task_runner.py:57} INFO - Started process 28045 to run task
[2025-09-16T02:29:33.724+0000] {standard_task_runner.py:84} INFO - Running: ['***', 'tasks', 'run', 'spotify_etl_pipeline', 'gold_transform', 'scheduled__2025-09-15T15:00:00+00:00', '--job-id', '950', '--raw', '--subdir', 'DAGS_FOLDER/spotify_dag.py', '--cfg-path', '/tmp/tmpu3mvi2je']
[2025-09-16T02:29:33.727+0000] {standard_task_runner.py:85} INFO - Job 950: Subtask gold_transform
[2025-09-16T02:29:33.781+0000] {task_command.py:415} INFO - Running <TaskInstance: spotify_etl_pipeline.gold_transform scheduled__2025-09-15T15:00:00+00:00 [running]> on host 537418afed42
[2025-09-16T02:29:34.024+0000] {taskinstance.py:1660} INFO - Exporting env vars: AIRFLOW_CTX_DAG_OWNER='***' AIRFLOW_CTX_DAG_ID='spotify_etl_pipeline' AIRFLOW_CTX_TASK_ID='gold_transform' AIRFLOW_CTX_EXECUTION_DATE='2025-09-15T15:00:00+00:00' AIRFLOW_CTX_TRY_NUMBER='5' AIRFLOW_CTX_DAG_RUN_ID='scheduled__2025-09-15T15:00:00+00:00'
[2025-09-16T02:29:34.029+0000] {taskinstance.py:1943} ERROR - Task failed with exception
Traceback (most recent call last):
  File "/home/airflow/.local/lib/python3.8/site-packages/airflow/operators/python.py", line 192, in execute
    return_value = self.execute_callable()
  File "/home/airflow/.local/lib/python3.8/site-packages/airflow/operators/python.py", line 209, in execute_callable
    return self.python_callable(*self.op_args, **self.op_kwargs)
  File "/opt/airflow/etl/db_utils.py", line 11, in run_sql_scripts
    cur.execute(sql)
psycopg2.errors.SyntaxError: syntax error at or near ")"
LINE 14: );
         ^

[2025-09-16T02:29:34.035+0000] {taskinstance.py:1400} INFO - Marking task as UP_FOR_RETRY. dag_id=spotify_etl_pipeline, task_id=gold_transform, execution_date=20250915T150000, start_date=20250916T022933, end_date=20250916T022934
[2025-09-16T02:29:34.043+0000] {standard_task_runner.py:104} ERROR - Failed to execute job 950 for task gold_transform (syntax error at or near ")"
LINE 14: );
         ^
; 28045)
[2025-09-16T02:29:34.051+0000] {local_task_job_runner.py:228} INFO - Task exited with return code 1
[2025-09-16T02:29:34.068+0000] {taskinstance.py:2784} INFO - 0 downstream tasks scheduled from follow-on schedule check
