[2025-09-15T06:04:02.505+0000] {taskinstance.py:1159} INFO - Dependencies all met for dep_context=non-requeueable deps ti=<TaskInstance: spotify_etl_pipeline.gold_transform scheduled__2025-09-15T05:00:00+00:00 [queued]>
[2025-09-15T06:04:02.510+0000] {taskinstance.py:1159} INFO - Dependencies all met for dep_context=requeueable deps ti=<TaskInstance: spotify_etl_pipeline.gold_transform scheduled__2025-09-15T05:00:00+00:00 [queued]>
[2025-09-15T06:04:02.511+0000] {taskinstance.py:1361} INFO - Starting attempt 1 of 6
[2025-09-15T06:04:02.519+0000] {taskinstance.py:1382} INFO - Executing <Task(PythonOperator): gold_transform> on 2025-09-15 05:00:00+00:00
[2025-09-15T06:04:02.525+0000] {standard_task_runner.py:57} INFO - Started process 30476 to run task
[2025-09-15T06:04:02.528+0000] {standard_task_runner.py:84} INFO - Running: ['***', 'tasks', 'run', 'spotify_etl_pipeline', 'gold_transform', 'scheduled__2025-09-15T05:00:00+00:00', '--job-id', '764', '--raw', '--subdir', 'DAGS_FOLDER/spotify_dag.py', '--cfg-path', '/tmp/tmpu23xqp_0']
[2025-09-15T06:04:02.529+0000] {standard_task_runner.py:85} INFO - Job 764: Subtask gold_transform
[2025-09-15T06:04:02.571+0000] {task_command.py:415} INFO - Running <TaskInstance: spotify_etl_pipeline.gold_transform scheduled__2025-09-15T05:00:00+00:00 [running]> on host 0d0cd054d690
[2025-09-15T06:04:02.756+0000] {taskinstance.py:1660} INFO - Exporting env vars: AIRFLOW_CTX_DAG_OWNER='***' AIRFLOW_CTX_DAG_ID='spotify_etl_pipeline' AIRFLOW_CTX_TASK_ID='gold_transform' AIRFLOW_CTX_EXECUTION_DATE='2025-09-15T05:00:00+00:00' AIRFLOW_CTX_TRY_NUMBER='1' AIRFLOW_CTX_DAG_RUN_ID='scheduled__2025-09-15T05:00:00+00:00'
[2025-09-15T06:04:02.763+0000] {logging_mixin.py:151} INFO - Executed sql/gold/listening_history/fact_listening_history.sql
[2025-09-15T06:04:02.765+0000] {taskinstance.py:1943} ERROR - Task failed with exception
Traceback (most recent call last):
  File "/home/airflow/.local/lib/python3.8/site-packages/airflow/operators/python.py", line 192, in execute
    return_value = self.execute_callable()
  File "/home/airflow/.local/lib/python3.8/site-packages/airflow/operators/python.py", line 209, in execute_callable
    return self.python_callable(*self.op_args, **self.op_kwargs)
  File "/opt/airflow/etl/db_utils.py", line 11, in run_sql_scripts
    cur.execute(sql)
psycopg2.errors.InvalidColumnReference: there is no unique or exclusion constraint matching the ON CONFLICT specification

[2025-09-15T06:04:02.772+0000] {taskinstance.py:1400} INFO - Marking task as UP_FOR_RETRY. dag_id=spotify_etl_pipeline, task_id=gold_transform, execution_date=20250915T050000, start_date=20250915T060402, end_date=20250915T060402
[2025-09-15T06:04:02.779+0000] {standard_task_runner.py:104} ERROR - Failed to execute job 764 for task gold_transform (there is no unique or exclusion constraint matching the ON CONFLICT specification
; 30476)
[2025-09-15T06:04:02.789+0000] {local_task_job_runner.py:228} INFO - Task exited with return code 1
[2025-09-15T06:04:02.802+0000] {taskinstance.py:2784} INFO - 0 downstream tasks scheduled from follow-on schedule check
