[2025-09-12T05:13:06.585+0000] {taskinstance.py:1159} INFO - Dependencies all met for dep_context=non-requeueable deps ti=<TaskInstance: spotify_etl_pipeline.gold_transform manual__2025-09-12T05:07:49.026358+00:00 [queued]>
[2025-09-12T05:13:06.593+0000] {taskinstance.py:1159} INFO - Dependencies all met for dep_context=requeueable deps ti=<TaskInstance: spotify_etl_pipeline.gold_transform manual__2025-09-12T05:07:49.026358+00:00 [queued]>
[2025-09-12T05:13:06.593+0000] {taskinstance.py:1361} INFO - Starting attempt 2 of 2
[2025-09-12T05:13:06.607+0000] {taskinstance.py:1382} INFO - Executing <Task(PythonOperator): gold_transform> on 2025-09-12 05:07:49.026358+00:00
[2025-09-12T05:13:06.626+0000] {standard_task_runner.py:57} INFO - Started process 23381 to run task
[2025-09-12T05:13:06.630+0000] {standard_task_runner.py:84} INFO - Running: ['***', 'tasks', 'run', 'spotify_etl_pipeline', 'gold_transform', 'manual__2025-09-12T05:07:49.026358+00:00', '--job-id', '284', '--raw', '--subdir', 'DAGS_FOLDER/spotify_dag.py', '--cfg-path', '/tmp/tmprzi0shrc']
[2025-09-12T05:13:06.633+0000] {standard_task_runner.py:85} INFO - Job 284: Subtask gold_transform
[2025-09-12T05:13:06.677+0000] {task_command.py:415} INFO - Running <TaskInstance: spotify_etl_pipeline.gold_transform manual__2025-09-12T05:07:49.026358+00:00 [running]> on host 0d0cd054d690
[2025-09-12T05:13:06.743+0000] {taskinstance.py:1660} INFO - Exporting env vars: AIRFLOW_CTX_DAG_OWNER='***' AIRFLOW_CTX_DAG_ID='spotify_etl_pipeline' AIRFLOW_CTX_TASK_ID='gold_transform' AIRFLOW_CTX_EXECUTION_DATE='2025-09-12T05:07:49.026358+00:00' AIRFLOW_CTX_TRY_NUMBER='2' AIRFLOW_CTX_DAG_RUN_ID='manual__2025-09-12T05:07:49.026358+00:00'
[2025-09-12T05:13:06.751+0000] {taskinstance.py:1943} ERROR - Task failed with exception
Traceback (most recent call last):
  File "/home/airflow/.local/lib/python3.8/site-packages/airflow/operators/python.py", line 192, in execute
    return_value = self.execute_callable()
  File "/home/airflow/.local/lib/python3.8/site-packages/airflow/operators/python.py", line 209, in execute_callable
    return self.python_callable(*self.op_args, **self.op_kwargs)
  File "/opt/airflow/etl/db_utils.py", line 11, in run_sql_scripts
    cur.execute(sql)
psycopg2.errors.UndefinedTable: missing FROM-clause entry for table "s"
LINE 6:     ROW_NUMBER() OVER (ORDER BY s.played_at_myt) AS fact_lis...
                                        ^

[2025-09-12T05:13:06.929+0000] {taskinstance.py:1400} INFO - Marking task as FAILED. dag_id=spotify_etl_pipeline, task_id=gold_transform, execution_date=20250912T050749, start_date=20250912T051306, end_date=20250912T051306
[2025-09-12T05:13:06.937+0000] {standard_task_runner.py:104} ERROR - Failed to execute job 284 for task gold_transform (missing FROM-clause entry for table "s"
LINE 6:     ROW_NUMBER() OVER (ORDER BY s.played_at_myt) AS fact_lis...
                                        ^
; 23381)
[2025-09-12T05:13:06.983+0000] {local_task_job_runner.py:228} INFO - Task exited with return code 1
[2025-09-12T05:13:06.997+0000] {taskinstance.py:2784} INFO - 0 downstream tasks scheduled from follow-on schedule check
